{"timestamp": "2025-07-02T00:59:43.843827", "level": "ERROR", "emoji": "\u274c", "message": "Test exception handled correctly", "category": "Test", "process_id": null, "session_id": "20250702_005943", "exception": {"type": "Exception", "message": "Test exception for error handling", "traceback": "Traceback (most recent call last):\n  File \"/mnt/data/projects/ProjectP/core/logging_integration_manager.py\", line 438, in test_integration\n    raise Exception(\"Test exception for error handling\")\nException: Test exception for error handling\n"}}
